<?xml version="1.0"?>
<!-- created with Phobos 0.8 -->
  <robot name="tank_bot" xmlns:xacro="http://www.ros.org/wiki/xacro">

    <xacro:include filename="$(find tank_bot)/urdf/tank_bot.gazebo" />
    <link name="robot_footprint"></link>

    <joint name="robot_footprint_joint" type="fixed">
      <origin xyz="0 0 0" rpy="0 0 0" />
      <parent link="robot_footprint"/>
      <child link="body" />
    </joint>

    <link name="body">
      <inertial>
        <origin xyz="0 0 0" rpy="0 0 0"/>
        <mass value="25.0"/>
        <inertia ixx="0.1" ixy="0" ixz="0" iyy="0.1" iyz="0" izz="0.1"/>
      </inertial>
      <visual name="visual_body">
        <origin xyz="0 0 0" rpy="0 0 0"/>
        <geometry>
          <mesh filename="package://tank_bot/meshes/dae/body.dae" scale="0.2 0.125 0.06938"/>
        </geometry>
      </visual>
      <collision name="collision_body">
        <origin xyz="0 0 0" rpy="0 0 0"/>
        <geometry>
          <box size="0.4 0.25 0.13875"/>
        </geometry>
      </collision>
    </link>

    <link name="camera">
      <inertial>
        <origin xyz="0 0 0" rpy="0 0 0"/>
        <mass value="0.1"/>
        <inertia ixx="0" ixy="0" ixz="0" iyy="0" iyz="0" izz="0"/>
      </inertial>
      <visual name="tank_bot::visual_camera">
        <origin xyz="0 0 0" rpy="1.5707 0 0"/>
        <geometry>
          <box size="0.05 0.05 0.05"/>
        </geometry>
      </visual>
      <collision name="collision_camera">
        <origin xyz="0 0 0" rpy="0 0 0"/>
        <geometry>
          <box size="0.05 0.05 0.05"/>
        </geometry>
      </collision>
    </link>

    <link name="hokuyo">
      <inertial>
        <origin xyz="0 0 0" rpy="0 0 0"/>
        <mass value="0.1"/>
        <inertia ixx="0" ixy="0" ixz="0" iyy="0" iyz="0" izz="0"/>
      </inertial>
      <visual name="visual_hokuyo">
        <origin xyz="0 0 0" rpy="1.5707 0 0"/>
        <geometry>
          <mesh filename="package://tank_bot/meshes/dae/hokuyo.dae" scale="1.0 1.0 1.0"/>
        </geometry>
        <material name="black-material"/>
      </visual>
      <collision name="collision_hokuyo">
        <origin xyz="0 0 0" rpy="0 0 0"/>
        <geometry>
          <box size="0.05 0.0701 0.05"/>
        </geometry>
      </collision>
    </link>

    <link name="left_wheel1">
      <inertial>
        <origin xyz="0 0 0" rpy="0 0 0"/>
        <mass value="3.0"/>
        <inertia ixx="0.11111" ixy="0" ixz="0" iyy="0.11111" iyz="0" izz="0.11111"/>
      </inertial>
      <visual name="visual_left_wheel1">
        <origin xyz="0 0 0" rpy="0 3.14159 0"/>
        <geometry>
          <cylinder radius="0.05" length="0.04"/>
        </geometry>
      </visual>
      <collision name="collision_left_wheel1">
        <origin xyz="0 0 0" rpy="0 3.14159 0"/>
        <geometry>
          <cylinder radius="0.05" length="0.04"/>
        </geometry>
      </collision>
    </link>

    <link name="left_wheel2">
      <inertial>
        <origin xyz="0 0 0" rpy="0 0 0"/>
        <mass value="3.0"/>
        <inertia ixx="0.11111" ixy="0" ixz="0" iyy="0.11111" iyz="0" izz="0.11111"/>
      </inertial>
      <visual name="visual_left_wheel2">
        <origin xyz="0 0 0" rpy="0 3.14159 0"/>
        <geometry>
          <cylinder radius="0.05" length="0.04"/>
        </geometry>
      </visual>
      <collision name="collision_left_wheel2">
        <origin xyz="0 0 0" rpy="0 3.14159 0"/>
        <geometry>
          <cylinder radius="0.05" length="0.04"/>
        </geometry>
      </collision>
    </link>

    <link name="left_wheel3">
      <inertial>
        <origin xyz="0 0 0" rpy="0 0 0"/>
        <mass value="3.0"/>
        <inertia ixx="0.11111" ixy="0" ixz="0" iyy="0.11111" iyz="0" izz="0.11111"/>
      </inertial>
      <visual name="visual_left_wheel3">
        <origin xyz="0 0 0" rpy="0 3.14159 0"/>
        <geometry>
          <cylinder radius="0.05" length="0.04"/>
        </geometry>
      </visual>
      <collision name="collision_left_wheel3">
        <origin xyz="0 0 0" rpy="0 3.14159 0"/>
        <geometry>
          <cylinder radius="0.05" length="0.04"/>
        </geometry>
      </collision>
    </link>

    <link name="right_wheel1">
      <inertial>
        <origin xyz="0 0 0" rpy="0 0 0"/>
        <mass value="3.0"/>
        <inertia ixx="0.11111" ixy="0" ixz="0" iyy="0.11111" iyz="0" izz="0.11111"/>
      </inertial>
      <visual name="visual_right_wheel1">
        <origin xyz="0 0 0" rpy="0 0 0"/>
        <geometry>
          <cylinder radius="0.05" length="0.04"/>
        </geometry>
      </visual>
      <collision name="collision_right_wheel1">
        <origin xyz="0 0 0" rpy="0 0 0"/>
        <geometry>
          <cylinder radius="0.05" length="0.04"/>
        </geometry>
      </collision>
    </link>

    <link name="right_wheel2">
      <inertial>
        <origin xyz="0 0 0" rpy="0 0 0"/>
        <mass value="3.0"/>
        <inertia ixx="0.11111" ixy="0" ixz="0" iyy="0.11111" iyz="0" izz="0.11111"/>
      </inertial>
      <visual name="visual_right_wheel2">
        <origin xyz="0 0 0" rpy="0 0 0"/>
        <geometry>
          <cylinder radius="0.05" length="0.04"/>
        </geometry>
      </visual>
      <collision name="collision_right_wheel2">
        <origin xyz="0 0 0" rpy="0 0 0"/>
        <geometry>
          <cylinder radius="0.05" length="0.04"/>
        </geometry>
      </collision>
    </link>

    <link name="right_wheel3">
      <inertial>
        <origin xyz="0 0 0" rpy="0 0 0"/>
        <mass value="3.0"/>
        <inertia ixx="0.11111" ixy="0" ixz="0" iyy="0.11111" iyz="0" izz="0.11111"/>
      </inertial>
      <visual name="visual_right_wheel3">
        <origin xyz="0 0 0" rpy="0 0 0"/>
        <geometry>
          <cylinder radius="0.05" length="0.04"/>
        </geometry>
      </visual>
      <collision name="collision_right_wheel3">
        <origin xyz="0 0 0" rpy="0 0 0"/>
        <geometry>
          <cylinder radius="0.05" length="0.04"/>
        </geometry>
      </collision>
    </link>

    <joint name="camera_jnt" type="fixed">
      <origin xyz="0.20865 0 0.02619" rpy="0 0 0"/>
      <parent link="body"/>
      <child link="camera"/>
    </joint>

    <joint name="hokuyo_jnt" type="fixed">
      <origin xyz="0.097893 -0.000438 0.10459" rpy="0 0 0"/>
      <parent link="body"/>
      <child link="hokuyo"/>
    </joint>

    <joint name="left_wheel1_jnt" type="continuous">
      <origin xyz="0.1293 0.14937 -0.04" rpy="1.5708 0 -3.14159"/>
      <parent link="body"/>
      <child link="left_wheel1"/>
      <axis xyz="0 0 1.0"/>
      <limit effort="10000.0" velocity="1000.0"/>
    </joint>

    <joint name="left_wheel2_jnt" type="continuous">
      <origin xyz="0.00699 0.14938 -0.04" rpy="1.5708 0 -3.14159"/>
      <parent link="body"/>
      <child link="left_wheel2"/>
      <axis xyz="0 0 1.0"/>
      <limit effort="10000.0" velocity="1000.0"/>
    </joint>

    <joint name="left_wheel3_jnt" type="continuous">
      <origin xyz="-0.11784 0.14938 -0.04" rpy="1.5708 0 -3.14159"/>
      <parent link="body"/>
      <child link="left_wheel3"/>
      <axis xyz="0 0 1.0"/>
      <limit effort="10000.0" velocity="1000.0"/>
    </joint>

    <joint name="right_wheel1_jnt" type="continuous">
      <origin xyz="0.12929 -0.14931 -0.04" rpy="1.5708 0 0"/>
      <parent link="body"/>
      <child link="right_wheel1"/>
      <axis xyz="0 0 1.0"/>
      <limit effort="10000.0" velocity="1000.0"/>
    </joint>

    <joint name="right_wheel2_jnt" type="continuous">
      <origin xyz="0.00699 -0.14931 -0.04" rpy="1.5708 0 0"/>
      <parent link="body"/>
      <child link="right_wheel2"/>
      <axis xyz="0 0 1.0"/>
      <limit effort="10000.0" velocity="1000.0"/>
    </joint>

    <joint name="right_wheel3_jnt" type="continuous">
      <origin xyz="-0.1178 -0.14931 -0.04" rpy="1.5708 0 0"/>
      <parent link="body"/>
      <child link="right_wheel3"/>
      <axis xyz="0 0 1.0"/>
      <limit effort="10000.0" velocity="1000.0"/>
    </joint>

    <material name="black-material">
      <color rgba="0.02031 0.02031 0.02031 1.0"/>
    </material>

  </robot>
